Workbook
Name IQ_CH: 110000
Name IQ_CQ: 5000
Name IQ_CY: 10000
Name IQ_DAILY: 500000
Name IQ_FH: 100000
Name IQ_FQ: 500
Name IQ_FY: 1000
Name IQ_LTM: 2000
Name IQ_MONTH: 15000
Name IQ_NTM: 6000
Name IQ_WEEK: 50000
Name IQ_YTD: 3000

Sheet Summary
A1: Portfolio Value at Risk (VaR) Analysis
A3: Portfolio Composition & Assumptions
A4: Asset | B4: Weight | C4: Allocated Value (Rs) | D4: Latest Price (Rs) | E4: Units Held
A5: Nestle India | B5: 0.2 | C5: =B5*B11 -> 100000 | D5: =Calculation!C16 -> 2058.4245 | E5: =C5/D5 -> 48.580843
A6: Pidilite Industries | B6: 0.2 | C6: =B6*B11 -> 100000 | D6: =Calculation!D16 -> 3071 | E6: =C6/D6 -> 32.562683
A7: Divi's Laboratories | B7: 0.2 | C7: =B7*B11 -> 100000 | D7: =Calculation!E16 -> 6638 | E7: =C7/D7 -> 15.064779
A8: Bosch Ltd | B8: 0.2 | C8: =B8*B11 -> 100000 | D8: =Calculation!F16 -> 39062.217 | E8: =C8/D8 -> 2.5600185
A9: UltraTech Cement | B9: 0.2 | C9: =B9*B11 -> 100000 | D9: =Calculation!G16 -> 11117 | E9: =C9/D9 -> 8.9952325
A10: Total Weight / Total Allocated Value (Rs) | B10: =SUM(B5:B9) -> 1 | C10: =SUM(C5:C9) -> 500000
A11: Portfolio Value Input (Rs) | B11: 500000
A13: Confidence Level 1 (1-tail) | B13: 0.95
A14: Confidence Level 2 (1-tail) | B14: 0.99
A15: Holding Period 1 (days) | B15: 1
A16: Holding Period 2 (days) | B16: 10
A17: Z-score @ Confidence Level 1 | B17: =_xlfn.NORM.S.INV(B13) -> 1.6448536
A18: Z-score @ Confidence Level 2 | B18: =_xlfn.NORM.S.INV(B14) -> 2.3263479
A19: Number of daily return observations | B19: =COUNT(Calculation!A16:A1253) -> 247
A22: 1. HISTORICAL SIMULATION VaR (Portfolio)
A23: Description | B23: Value
A24: Mean daily portfolio return | B24: =AVERAGE(Calculation!N16:N1252) -> 0.0002955902
A25: Std Dev of daily portfolio return | B25: =_xlfn.STDEV.S(Calculation!N16:N1252) -> 0.0099236269
A26: Worst-case percentile return @ Confidence 1 (5th pctile) | B26: =_xlfn.PERCENTILE.EXC(Calculation!N16:N1252,1-B13) -> -0.015851941
A27: Worst-case percentile return @ Confidence 2 (1st pctile) | B27: =_xlfn.PERCENTILE.EXC(Calculation!N16:N1252,1-B14) -> -0.031647715
A28: Historical VaR @ Confidence 1, 1-day (Rs) | B28: =-B26*$B$11 -> 7925.9705
A29: Historical VaR @ Confidence 2, 1-day (Rs) | B29: =-B27*$B$11 -> 15823.857
A30: Historical VaR @ Confidence 1, 10-day (Rs) | B30: =B28*SQRT(B16) -> 25064.119
A31: Historical VaR @ Confidence 2, 10-day (Rs) | B31: =B29*SQRT(B16) -> 50039.431
A34: 2. PARAMETRIC (VARIANCE-COVARIANCE) VaR (Portfolio)
A35: Description | B35: Value
A36: Mean daily portfolio return | B36: =B24 -> 0.0002955902
A37: Portfolio daily variance (w' Sigma w) | B37: {=MMULT(MMULT(TRANSPOSE(Summary!B5:B9),Calculation!AB4:AF8),Summary!B5:B9)} -> 9.8478371e-05
A38: Portfolio daily Std Dev (sigma_p) | B38: =SQRT(B37) -> 0.0099236269
A39: Parametric VaR @ Confidence 1, 1-day (Rs) | B39: =(B17*B38-B36)*$B$11 -> 8013.6618
A40: Parametric VaR @ Confidence 2, 1-day (Rs) | B40: =(B18*B38-B36)*$B$11 -> 11395.109
A41: Parametric VaR @ Confidence 1, 10-day (Rs) | B41: =B39*SQRT(B16) -> 25341.424
A42: Parametric VaR @ Confidence 2, 10-day (Rs) | B42: =B40*SQRT(B16) -> 36034.499
A45: 3. STANDALONE (UNDIVERSIFIED) VaR BY ASSET, 1-day
A46: Asset | B46: Allocated Value (Rs) | C46: Daily Std Dev | D46: Hist. VaR @ Conf.1 (Rs) | E46: Hist. VaR @ Conf.2 (Rs) | F46: Param. VaR @ Conf.1 (Rs) | G46: Param. VaR @ Conf.2 (Rs)
A47: Nestle India | B47: =C5 -> 100000 | C47: =_xlfn.STDEV.S(Calculation!I16:I1252) -> 0.01323901 | D47: =-_xlfn.PERCENTILE.EXC(Calculation!I16:I1252,1-B13)*B47 -> 1901.0048 | E47: =-_xlfn.PERCENTILE.EXC(Calculation!I16:I1252,1-B14)*B47 -> 3772.0078 | F47: =B17*C47*B47 -> 2177.6234 | G47: =B18*C47*B47 -> 3079.8543
A48: Pidilite Industries | B48: =C6 -> 100000 | C48: =_xlfn.STDEV.S(Calculation!J16:J1252) -> 0.012982775 | D48: =-_xlfn.PERCENTILE.EXC(Calculation!J16:J1252,1-B13)*B48 -> 2073.8366 | E48: =-_xlfn.PERCENTILE.EXC(Calculation!J16:J1252,1-B14)*B48 -> 3530.1901 | F48: =B17*C48*B48 -> 2135.4765 | G48: =B18*C48*B48 -> 3020.2452
...

Sheet Calculation
A1: Calculation of Historical VaR (also called Historical Simulation Method) | S1: Calculation of Parametric VaR (also called Delta-Normal Method) | AA1: Variance-Covariance Matrix | AX1: Instructions:
AX2: PLEASE NOTE THIS IS ONLY A BROAD TEMPLATE WITH DETAILED INSTRUCTIONS; YOU WILL
A3: Portfolio Weights | U3: Nestle_India | V3: Pidilite_Industries | W3: Divis_Laboratories | X3: Bosch | Y3: UltraTech_Cement | AA3: Σ | AB3: Nestle_India | AC3: Pidilite_Industries | AD3: Divis_Laboratories | AE3: Bosch | AF3: UltraTech_Cement | AH3: Weight(w) | AI3: Weight T | AJ3: =AH4 -> 0.2 | AK3: =AH5 -> 0.2 | AL3: =AH6 -> 0.2 | AM3: =AH7 -> 0.2 | AN3: =AH8 -> 0.2 | AX3: NEED TO FOLLOW THE INSTRUCTIONS AND DO NECESSARY CALCULATIONS
B4: Stock Name | C4: Amount Invested | D4: Weight | E4: Bseline Price | H4: HS VaR: | I4: =Q11 -> -7925.9705 | T4: St. Dev. | U4: =_xlfn.STDEV.S(I16:I261) -> 0.01323901 | V4: =_xlfn.STDEV.S(J16:J261) -> 0.012982775 | W4: =_xlfn.STDEV.S(K16:K261) -> 0.013993616 | X4: =_xlfn.STDEV.S(L16:L261) -> 0.018395446 | Y4: =_xlfn.STDEV.S(M16:M261) -> 0.014400449 | AA4: Nestle_India | AB4: =U5 -> 0.00017527139 | AC4: =_xlfn.COVARIANCE.S(I16:I261,J16:J261) -> 5.0772525e-05 | AD4: =_xlfn.COVARIANCE.S(I16:I261,K16:K261) -> 3.4108087e-05 | AE4: =_xlfn.COVARIANCE.S(I16:I261,L16:L261) -> 5.9725361e-05 | AF4: =_xlfn.COVARIANCE.S(I16:I261,M16:M261) -> 7.6565591e-05 | AH4: =D5 -> 0.2 | AX4: 1) Select 5 equities that are listed on either the NSE or BSE stock exchange and enter their names in B4 through B8 (for reference)
A5: Asset 1 | B5: Nestle_India | C5: 100000 | D5: =C5/$C$10 -> 0.2 | E5: 1375.85 | T5: Variance | U5: =U4^2 -> 0.00017527139 | V5: =V4^2 -> 0.00016855245 | W5: =W4^2 -> 0.00019582129 | X5: =X4^2 -> 0.00033839244 | Y5: =Y4^2 -> 0.00020737292 | AA5: Pidilite_Industries | AB5: =AC4 -> 5.0772525e-05 | AC5: =V5 -> 0.00016855245 | AD5: =_xlfn.COVARIANCE.S(K16:K261,J16:J261) -> 3.2978147e-05 | AE5: =_xlfn.COVARIANCE.S(J16:J261,L16:L261) -> 9.6772407e-05 | AF5: =_xlfn.COVARIANCE.S(M16:M261,J16:J261) -> 9.8631247e-05 | AH5: =D6 -> 0.2 | AX5: 2) Decide on investment amounts for each of them and enter in cells C4 through C8
A6: Asset 2 | B6: Pidilite_Industries | C6: 100000 | D6: =C6/$C$10 -> 0.2 | E6: 3046.9 | AA6: Divis_Laboratories | AB6: =AD4 -> 3.4108087e-05 | AC6: =AD5 -> 3.2978147e-05 | AD6: =W5 -> 0.00019582129 | AE6: =_xlfn.COVARIANCE.S(K16:K261,L16:L261) -> 7.2247227e-05 | AF6: =_xlfn.COVARIANCE.S(K16:K261,M16:M261) -> 5.0655132e-05 | AH6: =D7 -> 0.2 | AX6: 3) Caculate the weights in cells D4:D8
A7: Asset 3 | B7: Divis_Laboratories | C7: 100000 | D7: =C7/$C$10 -> 0.2 | E7: 6725 | AA7: Bosch | AB7: =AE4 -> 5.9725361e-05 | AC7: =AE5 -> 9.6772407e-05 | AD7: =AE6 -> 7.2247227e-05 | AE7: =X5 -> 0.00033839244 | AF7: =_xlfn.COVARIANCE.S(L16:L261,M16:M261) -> 0.00011581867 | AH7: =D8 -> 0.2 | AX7: 4) Download the closing prices of the five stocks for the past one year and enter in c15:g264; if more rows are needed please extend the matrix accordingly
A8: Asset 4 | B8: Bosch | C8: 100000 | D8: =C8/$C$10 -> 0.2 | E8: 31520 | AA8: UltraTech_Cement | AB8: =AF4 -> 7.6565591e-05 | AC8: =AF5 -> 9.8631247e-05 | AD8: =AF6 -> 5.0655132e-05 | AE8: =AF7 -> 0.00011581867 | AF8: =Y5 -> 0.00020737292 | AH8: =D9 -> 0.2 | AX8: 5) Calculate the log returns in cells I15:M264; extend as necessary; HOPE YOU KNOW HOW TO CALCULATE LOG RETURNS?!
A9: Asset 5 | B9: UltraTech_Cement | C9: 100000 | D9: =C9/$C$10 -> 0.2 | E9: 11323 | T9: Portfolio Variance | U9: {=MMULT(MMULT(AJ3:AN3,AB4:AF8),AH4:AH8)} -> 9.8478371e-05 | AX9: 6) Calculate the weighted average portfolio return in cells O15:G264; extend as necessary
A10: Total | C10: =SUM(C5:C9) -> 500000 | D10: =SUM(D5:D9) -> 1 | T10: Portfolio Std. Dev | U10: =SQRT(U9) -> 0.0099236269 | AX10: 8) Using appropriate excel function calculate the 95% (percentile) VaR - both percentage VaR and Dollar/ Rupee VaR
P11: HS VaR Rs | Q11: =_xlfn.PERCENTILE.EXC($P$16:$P$1252,0.05) -> -7925.9705 | AX11: 9) If you are not sure of the excel function you can also sort/ rank order the returns and identify the 95% VaR
P12: HS VaR % | Q12: =_xlfn.PERCENTILE.EXC(N16:N1252,0.05) -> -0.015851941 | AX12: 10) This is the broad guidance, ask me if any questions; but before that please read the appropriate books (on VaR)
AX13: DO NOT COPY FROM OTHERS; PLEASE DO INDEPENDENT WORK
C14: Closing Prices | I14: Log Returns
A15: Observation | B15: Date | C15: Nestle_India | D15: Pidilite_Industries | E15: Divis_Laboratories | F15: Bosch | G15: UltraTech_Cement | I15: Nestle_India | J15: Pidilite_Industries | K15: Divis_Laboratories | L15: Bosch | M15: UltraTech_Cement | N15: Portfolio Return | P15: Portfolio PnL
A16: 1 | B16: 46185 | C16: =$E$5*(1+'Nestlé India Limited'!B52/100) -> 2058.4245 | D16: =$E$6*(1+'Pidilite Industries Limited'!B52/100) -> 3071 | E16: =$E$7*(1+'Divi''s Laboratories Limited'!B52/100) -> 6638 | F16: =$E$8*(1+'Bosch Limited'!B52/100) -> 39062.217 | G16: =$E$9*(1+'UltraTech Cement Limited'!B52/100) -> 11117 | I16: =LN(C16/C17) -> -0.032816785 | J16: =LN(D16/D17) -> 0.024191273 | K16: =LN(E16/E17) -> -0.0026328672 | L16: =LN(F16/F17) -> 0.039403656 | M16: =LN(G16/G17) -> 0.026155407 | N16: =$D$5*I16+$D$6*J16+$D$7*K16+$D$8*L16+$D$9*M16 -> 0.010860137 | P16: =$C$10*N16 -> 5430.0683
A17: 2 | B17: 46184 | C17: =$E$5*(1+'Nestlé India Limited'!B53/100) -> 2127.096 | D17: =$E$6*(1+'Pidilite Industries Limited'!B53/100) -> 2997.6 | E17: =$E$7*(1+'Divi''s Laboratories Limited'!B53/100) -> 6655.5 | F17: =$E$8*(1+'Bosch Limited'!B53/100) -> 37552.954 | G17: =$E$9*(1+'UltraTech Cement Limited'!B53/100) -> 10830 | I17: =LN(C17/C18) -> -0.011434291 | J17: =LN(D17/D18) -> -0.0051242917 | K17: =LN(E17/E18) -> 0.0025575462 | L17: =LN(F17/F18) -> -0.0063322606 | M17: =LN(G17/G18) -> -0.0033185871 | N17: =$D$5*I17+$D$6*J17+$D$7*K17+$D$8*L17+$D$9*M17 -> -0.0047303768 | P17: =$C$10*N17 -> -2365.1884
A18: 3 | B18: 46183 | C18: =$E$5*(1+'Nestlé India Limited'!B54/100) -> 2151.5575 | D18: =$E$6*(1+'Pidilite Industries Limited'!B54/100) -> 3013 | E18: =$E$7*(1+'Divi''s Laboratories Limited'!B54/100) -> 6638.5 | F18: =$E$8*(1+'Bosch Limited'!B54/100) -> 37791.503 | G18: =$E$9*(1+'UltraTech Cement Limited'!B54/100) -> 10866 | I18: =LN(C18/C19) -> 0.019449446 | J18: =LN(D18/D19) -> 0.016531515 | K18: =LN(E18/E19) -> -0.017100816 | L18: =LN(F18/F19) -> -0.00080293506 | M18: =LN(G18/G19) -> -0.0041328065 | N18: =$D$5*I18+$D$6*J18+$D$7*K18+$D$8*L18+$D$9*M18 -> 0.0027888805 | P18: =$C$10*N18 -> 1394.4403
A19: 4 | B19: 46182 | C19: =$E$5*(1+'Nestlé India Limited'!B55/100) -> 2110.1152 | D19: =$E$6*(1+'Pidilite Industries Limited'!B55/100) -> 2963.6 | E19: =$E$7*(1+'Divi''s Laboratories Limited'!B55/100) -> 6753 | F19: =$E$8*(1+'Bosch Limited'!B55/100) -> 37821.86 | G19: =$E$9*(1+'UltraTech Cement Limited'!B55/100) -> 10911 | I19: =LN(C19/C20) -> 0.0077940498 | J19: =LN(D19/D20) -> 0.014958125 | K19: =LN(E19/E20) -> 0.034959112 | L19: =LN(F19/F20) -> 0.033895624 | M19: =LN(G19/G20) -> 0.010688391 | N19: =$D$5*I19+$D$6*J19+$D$7*K19+$D$8*L19+$D$9*M19 -> 0.02045906 | P19: =$C$10*N19 -> 10229.53 | T19: Parametric VaR:
A20: 5 | B20: 46181 | C20: =$E$5*(1+'Nestlé India Limited'!B56/100) -> 2093.7328 | D20: =$E$6*(1+'Pidilite Industries Limited'!B56/100) -> 2919.6 | E20: =$E$7*(1+'Divi''s Laboratories Limited'!B56/100) -> 6521 | F20: =$E$8*(1+'Bosch Limited'!B56/100) -> 36561.348 | G20: =$E$9*(1+'UltraTech Cement Limited'!B56/100) -> 10795 | I20: =LN(C20/C21) -> 0.0084676334 | J20: =LN(D20/D21) -> -0.011442708 | K20: =LN(E20/E21) -> -0.015520701 | L20: =LN(F20/F21) -> -0.01866546 | M20: =LN(G20/G21) -> -0.010780037 | N20: =$D$5*I20+$D$6*J20+$D$7*K20+$D$8*L20+$D$9*M20 -> -0.0095882544 | P20: =$C$10*N20 -> -4794.1272 | U20: Mean daily return | V20: =AVERAGE(N16:N261) -> 0.0002955902
A21: 6 | B21: 46178 | C21: =$E$5*(1+'Nestlé India Limited'!B57/100) -> 2076.0786 | D21: =$E$6*(1+'Pidilite Industries Limited'!B57/100) -> 2953.2 | E21: =$E$7*(1+'Divi''s Laboratories Limited'!B57/100) -> 6623 | F21: =$E$8*(1+'Bosch Limited'!B57/100) -> 37250.191 | G21: =$E$9*(1+'UltraTech Cement Limited'!B57/100) -> 10912 | I21: =LN(C21/C22) -> 0.0046951834 | J21: =LN(D21/D22) -> 0.0037317274 | K21: =LN(E21/E22) -> 0.0040092342 | L21: =LN(F21/F22) -> 0.0062746033 | M21: =LN(G21/G22) -> -0.0077594072 | N21: =$D$5*I21+$D$6*J21+$D$7*K21+$D$8*L21+$D$9*M21 -> 0.0021902682 | P21: =$C$10*N21 -> 1095.1341 | U21: Z-Score | V21: =_xlfn.NORM.S.INV(0.95) -> 1.6448536
A22: 7 | B22: 46177 | C22: =$E$5*(1+'Nestlé India Limited'!B58/100) -> 2066.3539 | D22: =$E$6*(1+'Pidilite Industries Limited'!B58/100) -> 2942.2 | E22: =$E$7*(1+'Divi''s Laboratories Limited'!B58/100) -> 6596.5 | F22: =$E$8*(1+'Bosch Limited'!B58/100) -> 37017.192 | G22: =$E$9*(1+'UltraTech Cement Limited'!B58/100) -> 10997 | I22: =LN(C22/C23) -> -0.0082560181 | J22: =LN(D22/D23) -> 0.0012923853 | K22: =LN(E22/E23) -> 0.0030365164 | L22: =LN(F22/F23) -> -0.019141741 | M22: =LN(G22/G23) -> -0.009412686 | N22: =$D$5*I22+$D$6*J22+$D$7*K22+$D$8*L22+$D$9*M22 -> -0.0064963087 | P22: =$C$10*N22 -> -3248.1544 | U22: Portfolio Std. Dev | V22: =U10 -> 0.0099236269
A23: 8 | B23: 46176 | C23: =$E$5*(1+'Nestlé India Limited'!B59/100) -> 2083.4844 | D23: =$E$6*(1+'Pidilite Industries Limited'!B59/100) -> 2938.4 | E23: =$E$7*(1+'Divi''s Laboratories Limited'!B59/100) -> 6576.5 | F23: =$E$8*(1+'Bosch Limited'!B59/100) -> 37732.591 | G23: =$E$9*(1+'UltraTech Cement Limited'!B59/100) -> 11101 | I23: =LN(C23/C24) -> -0.0043349822 | J23: =LN(D23/D24) -> 0.0099870862 | K23: =LN(E23/E24) -> 0.0066364331 | L23: =LN(F23/F24) -> 0.013190746 | M23: =LN(G23/G24) -> -0.0057486909 | N23: =$D$5*I23+$D$6*J23+$D$7*K23+$D$8*L23+$D$9*M23 -> 0.0039461184 | P23: =$C$10*N23 -> 1973.0592 | U23: Portfolio Value | V23: =C10 -> 500000
A24: 9 | B24: 46175 | C24: =$E$5*(1+'Nestlé India Limited'!B60/100) -> 2092.5359 | D24: =$E$6*(1+'Pidilite Industries Limited'!B60/100) -> 2909.2 | E24: =$E$7*(1+'Divi''s Laboratories Limited'!B60/100) -> 6533 | F24: =$E$8*(1+'Bosch Limited'!B60/100) -> 37238.138 | G24: =$E$9*(1+'UltraTech Cement Limited'!B60/100) -> 11165 | I24: =LN(C24/C25) -> 0.0054126846 | J24: =LN(D24/D25) -> -0.0017858374 | K24: =LN(E24/E25) -> -0.0031330022 | L24: =LN(F24/F25) -> 0.01553623 | M24: =LN(G24/G25) -> -0.005982962 | N24: =$D$5*I24+$D$6*J24+$D$7*K24+$D$8*L24+$D$9*M24 -> 0.0020094226 | P24: =$C$10*N24 -> 1004.7113
A25: 10 | B25: 46174 | C25: =$E$5*(1+'Nestlé India Limited'!B61/100) -> 2081.2402 | D25: =$E$6*(1+'Pidilite Industries Limited'!B61/100) -> 2914.4 | E25: =$E$7*(1+'Divi''s Laboratories Limited'!B61/100) -> 6553.5 | F25: =$E$8*(1+'Bosch Limited'!B61/100) -> 36664.069 | G25: =$E$9*(1+'UltraTech Cement Limited'!B61/100) -> 11232 | I25: =LN(C25/C26) -> -0.022567101 | J25: =LN(D25/D26) -> -0.017415406 | K25: =LN(E25/E26) -> -0.017170726 | L25: =LN(F25/F26) -> -0.00037912469 | M25: =LN(G25/G26) -> -0.022013744 | N25: =$D$5*I25+$D$6*J25+$D$7*K25+$D$8*L25+$D$9*M25 -> -0.01590922 | P25: =$C$10*N25 -> -7954.6102 | U25: Par. VaR Rs | V25: =(V20-V21*V22)*V23 -> -8013.6618
A26: 11 | B26: 46171 | C26: =$E$5*(1+'Nestlé India Limited'!B62/100) -> 2128.7418 | D26: =$E$6*(1+'Pidilite Industries Limited'!B62/100) -> 2965.6 | E26: =$E$7*(1+'Divi''s Laboratories Limited'!B62/100) -> 6667 | F26: =$E$8*(1+'Bosch Limited'!B62/100) -> 36677.972 | G26: =$E$9*(1+'UltraTech Cement Limited'!B62/100) -> 11482 | I26: =LN(C26/C27) -> -0.0031927051 | J26: =LN(D26/D27) -> 0.0014172434 | K26: =LN(E26/E27) -> -0.019384914 | L26: =LN(F26/F27) -> 0.017749833 | M26: =LN(G26/G27) -> -0.017867637 | N26: =$D$5*I26+$D$6*J26+$D$7*K26+$D$8*L26+$D$9*M26 -> -0.0042556359 | P26: =$C$10*N26 -> -2127.8179 | U26: Par. VaR % | V26: =(V20-V21*V22) -> -0.016027324
A27: 12 | B27: 46169 | C27: =$E$5*(1+'Nestlé India Limited'!B64/100) -> 2135.5491 | D27: =$E$6*(1+'Pidilite Industries Limited'!B64/100) -> 2961.4 | E27: =$E$7*(1+'Divi''s Laboratories Limited'!B64/100) -> 6797.5 | F27: =$E$8*(1+'Bosch Limited'!B64/100) -> 36032.688 | G27: =$E$9*(1+'UltraTech Cement Limited'!B64/100) -> 11689 | I27: =LN(C27/C28) -> -0.0010503099 | J27: =LN(D27/D28) -> 0.0014868886 | K27: =LN(E27/E28) -> 0.0065680469 | L27: =LN(F27/F28) -> 0.0048667584 | M27: =LN(G27/G28) -> 0.005662335 | N27: =$D$5*I27+$D$6*J27+$D$7*K27+$D$8*L27+$D$9*M27 -> 0.0035067438 | P27: =$C$10*N27 -> 1753.3719
A28: 13 | B28: 46168 | C28: =$E$5*(1+'Nestlé India Limited'!B65/100) -> 2137.7932 | D28: =$E$6*(1+'Pidilite Industries Limited'!B65/100) -> 2957 | E28: =$E$7*(1+'Divi''s Laboratories Limited'!B65/100) -> 6753 | F28: =$E$8*(1+'Bosch Limited'!B65/100) -> 35857.751 | G28: =$E$9*(1+'UltraTech Cement Limited'!B65/100) -> 11623 | I28: =LN(C28/C29) -> 0.010623803 | J28: =LN(D28/D29) -> 0.00087965631 | K28: =LN(E28/E29) -> -0.0005181539 | L28: =LN(F28/F29) -> -0.0130648 | M28: =LN(G28/G29) -> -0.0088227049 | N28: =$D$5*I28+$D$6*J28+$D$7*K28+$D$8*L28+$D$9*M28 -> -0.00218044 | P28: =$C$10*N28 -> -1090.22
A29: 14 | B29: 46167 | C29: =$E$5*(1+'Nestlé India Limited'!B66/100) -> 2115.202 | D29: =$E$6*(1+'Pidilite Industries Limited'!B66/100) -> 2954.4 | E29: =$E$7*(1+'Divi''s Laboratories Limited'!B66/100) -> 6756.5 | F29: =$E$8*(1+'Bosch Limited'!B66/100) -> 36329.299 | G29: =$E$9*(1+'UltraTech Cement Limited'!B66/100) -> 11726 | I29: =LN(C29/C30) -> -0.0066618741 | J29: =LN(D29/D30) -> -0.00081201791 | K29: =LN(E29/E30) -> -0.019130572 | L29: =LN(F29/F30) -> 0.0073462235 | M29: =LN(G29/G30) -> 0.013479491 | N29: =$D$5*I29+$D$6*J29+$D$7*K29+$D$8*L29+$D$9*M29 -> -0.0011557498 | P29: =$C$10*N29 -> -577.87491
A30: 15 | B30: 46164 | C30: =$E$5*(1+'Nestlé India Limited'!B67/100) -> 2129.3402 | D30: =$E$6*(1+'Pidilite Industries Limited'!B67/100) -> 2956.8 | E30: =$E$7*(1+'Divi''s Laboratories Limited'!B67/100) -> 6887 | F30: =$E$8*(1+'Bosch Limited'!B67/100) -> 36063.394 | G30: =$E$9*(1+'UltraTech Cement Limited'!B67/100) -> 11569 | I30: =LN(C30/C31) -> 0.012194195 | J30: =LN(D30/D31) -> 0.003795071 | K30: =LN(E30/E31) -> 0.0042197225 | L30: =LN(F30/F31) -> 0.02410966 | M30: =LN(G30/G31) -> 0.0082455009 | N30: =$D$5*I30+$D$6*J30+$D$7*K30+$D$8*L30+$D$9*M30 -> 0.01051283 | P30: =$C$10*N30 -> 5256.415
A31: 16 | B31: 46163 | C31: =$E$5*(1+'Nestlé India Limited'!B68/100) -> 2103.5323 | D31: =$E$6*(1+'Pidilite Industries Limited'!B68/100) -> 2945.6 | E31: =$E$7*(1+'Divi''s Laboratories Limited'!B68/100) -> 6858 | F31: =$E$8*(1+'Bosch Limited'!B68/100) -> 35204.316 | G31: =$E$9*(1+'UltraTech Cement Limited'!B68/100) -> 11474 | I31: =LN(C31/C32) -> -0.010084119 | J31: =LN(D31/D32) -> 0.011747164 | K31: =LN(E31/E32) -> -0.0050905499 | L31: =LN(F31/F32) -> -0.045095262 | M31: =LN(G31/G32) -> 0.0056810886 | N31: =$D$5*I31+$D$6*J31+$D$7*K31+$D$8*L31+$D$9*M31 -> -0.0085683355 | P31: =$C$10*N31 -> -4284.1678
A32: 17 | B32: 46162 | C32: =$E$5*(1+'Nestlé India Limited'!B69/100) -> 2124.8519 | D32: =$E$6*(1+'Pidilite Industries Limited'!B69/100) -> 2911.2 | E32: =$E$7*(1+'Divi''s Laboratories Limited'!B69/100) -> 6893 | F32: =$E$8*(1+'Bosch Limited'!B69/100) -> 36828.203 | G32: =$E$9*(1+'UltraTech Cement Limited'!B69/100) -> 11409 | I32: =LN(C32/C33) -> -0.0078550041 | J32: =LN(D32/D33) -> -0.00013739095 | K32: =LN(E32/E33) -> -0.0027526276 | L32: =LN(F32/F33) -> -0.0076053298 | M32: =LN(G32/G33) -> 0.0036001268 | N32: =$D$5*I32+$D$6*J32+$D$7*K32+$D$8*L32+$D$9*M32 -> -0.0029500451 | P32: =$C$10*N32 -> -1475.0226
A33: 18 | B33: 46161 | C33: =$E$5*(1+'Nestlé India Limited'!B70/100) -> 2141.6083 | D33: =$E$6*(1+'Pidilite Industries Limited'!B70/100) -> 2911.6 | E33: =$E$7*(1+'Divi''s Laboratories Limited'!B70/100) -> 6912 | F33: =$E$8*(1+'Bosch Limited'!B70/100) -> 37109.361 | G33: =$E$9*(1+'UltraTech Cement Limited'!B70/100) -> 11368 | I33: =LN(C33/C34) -> -0.00066344259 | J33: =LN(D33/D34) -> 0.0038540997 | K33: =LN(E33/E34) -> 0.011202561 | L33: =LN(F33/F34) -> -0.001514957 | M33: =LN(G33/G34) -> -0.016834974 | N33: =$D$5*I33+$D$6*J33+$D$7*K33+$D$8*L33+$D$9*M33 -> -0.00079134247 | P33: =$C$10*N33 -> -395.67124
A34: 19 | B34: 46160 | C34: =$E$5*(1+'Nestlé India Limited'!B71/100) -> 2143.0296 | D34: =$E$6*(1+'Pidilite Industries Limited'!B71/100) -> 2900.4 | E34: =$E$7*(1+'Divi''s Laboratories Limited'!B71/100) -> 6835 | F34: =$E$8*(1+'Bosch Limited'!B71/100) -> 37165.623 | G34: =$E$9*(1+'UltraTech Cement Limited'!B71/100) -> 11561 | I34: =LN(C34/C35) -> 0.0014671467 | J34: =LN(D34/D35) -> -0.011995072 | K34: =LN(E34/E35) -> 0.010959618 | L34: =LN(F34/F35) -> -0.014433295 | M34: =LN(G34/G35) -> 0.0064214035 | N34: =$D$5*I34+$D$6*J34+$D$7*K34+$D$8*L34+$D$9*M34 -> -0.0015160397 | P34: =$C$10*N34 -> -758.01985
A35: 20 | B35: 46157 | C35: =$E$5*(1+'Nestlé India Limited'!B72/100) -> 2139.8878 | D35: =$E$6*(1+'Pidilite Industries Limited'!B72/100) -> 2935.4 | E35: =$E$7*(1+'Divi''s Laboratories Limited'!B72/100) -> 6760.5 | F35: =$E$8*(1+'Bosch Limited'!B72/100) -> 37705.935 | G35: =$E$9*(1+'UltraTech Cement Limited'!B72/100) -> 11487 | I35: =LN(C35/C36) -> -0.020312468 | J35: =LN(D35/D36) -> -0.010909815 | K35: =LN(E35/E36) -> -0.023535657 | L35: =LN(F35/F36) -> 0.019770743 | M35: =LN(G35/G36) -> -0.017688886 | N35: =$D$5*I35+$D$6*J35+$D$7*K35+$D$8*L35+$D$9*M35 -> -0.010535217 | P35: =$C$10*N35 -> -5267.6084
A36: 21 | B36: 46156 | C36: =$E$5*(1+'Nestlé India Limited'!B73/100) -> 2183.7986 | D36: =$E$6*(1+'Pidilite Industries Limited'!B73/100) -> 2967.6 | E36: =$E$7*(1+'Divi''s Laboratories Limited'!B73/100) -> 6921.5 | F36: =$E$8*(1+'Bosch Limited'!B73/100) -> 36967.782 | G36: =$E$9*(1+'UltraTech Cement Limited'!B73/100) -> 11692 | I36: =LN(C36/C37) -> -0.0060788385 | J36: =LN(D36/D37) -> 0.026081904 | K36: =LN(E36/E37) -> 0.018298305 | L36: =LN(F36/F37) -> 0.017506192 | M36: =LN(G36/G37) -> 0.010230048 | N36: =$D$5*I36+$D$6*J36+$D$7*K36+$D$8*L36+$D$9*M36 -> 0.013207522 | P36: =$C$10*N36 -> 6603.7612
A37: 22 | B37: 46155 | C37: =$E$5*(1+'Nestlé India Limited'!B74/100) -> 2197.114 | D37: =$E$6*(1+'Pidilite Industries Limited'!B74/100) -> 2891.2 | E37: =$E$7*(1+'Divi''s Laboratories Limited'!B74/100) -> 6796 | F37: =$E$8*(1+'Bosch Limited'!B74/100) -> 36326.249 | G37: =$E$9*(1+'UltraTech Cement Limited'!B74/100) -> 11573 | I37: =LN(C37/C38) -> -3.404661e-05 | J37: =LN(D37/D38) -> -0.0051059243 | K37: =LN(E37/E38) -> 0.022620012 | L37: =LN(F37/F38) -> -0.0046753446 | M37: =LN(G37/G38) -> 0.0049374261 | N37: =$D$5*I37+$D$6*J37+$D$7*K37+$D$8*L37+$D$9*M37 -> 0.0035484245 | P37: =$C$10*N37 -> 1774.2123
A38: 23 | B38: 46154 | C38: =$E$5*(1+'Nestlé India Limited'!B75/100) -> 2197.1888 | D38: =$E$6*(1+'Pidilite Industries Limited'!B75/100) -> 2906 | E38: =$E$7*(1+'Divi''s Laboratories Limited'!B75/100) -> 6644 | F38: =$E$8*(1+'Bosch Limited'!B75/100) -> 36496.484 | G38: =$E$9*(1+'UltraTech Cement Limited'!B75/100) -> 11516 | I38: =LN(C38/C39) -> -0.0082053829 | J38: =LN(D38/D39) -> 0.010933608 | K38: =LN(E38/E39) -> -0.010480707 | L38: =LN(F38/F39) -> -0.02162859 | M38: =LN(G38/G39) -> -0.029939795 | N38: =$D$5*I38+$D$6*J38+$D$7*K38+$D$8*L38+$D$9*M38 -> -0.011864173 | P38: =$C$10*N38 -> -5932.0866
... A44: 29 | B44: 46146 | C44: =$E$5*(1+'Nestlé India Limited'!B81/100) -> 2179.7591 | D44: =$E$6*(1+'Pidilite Industries Limited'!B81/100) -> 2729.2 | E44: =$E$7*(1+'Divi''s Laboratories Limited'!B81/100) -> 6619.5 | F44: =$E$8*(1+'Bosch Limited'!B81/100) -> 35831.496 | G44: =$E$9*(1+'UltraTech Cement Limited'!B81/100) -> 11758 | I44: =LN(C44/C45) -> -0.00058324043 | J44: =LN(D44/D45) -> -0.0081013471 | K44: =LN(E44/E45) -> 0.01783312 | L44: =LN(F44/F45) -> -0.0051438975 | M44: =LN(G44/G45) -> 0.014736387 | N44: =$D$5*I44+$D$6*J44+$D$7*K44+$D$8*L44+$D$9*M44 -> 0.0037482045 | P44: =$C$10*N44 -> 1874.1022
A45: 30 | B45: 46142 | C45: =$E$5*(1+'Nestlé India Limited'!B83/100) -> 2181.0308 | D45: =$E$6*(1+'Pidilite Industries Limited'!B83/100) -> 2751.4 | E45: =$E$7*(1+'Divi''s Laboratories Limited'!B83/100) -> 6502.5 | F45: =$E$8*(1+'Bosch Limited'!B83/100) -> 36016.284 | G45: =$E$9*(1+'UltraTech Cement Limited'!B83/100) -> 11586 | I45: =LN(C45/C46) -> -0.005677364 | J45: =LN(D45/D46) -> -0.0096213713 | K45: =LN(E45/E46) -> -0.0048325948 | L45: =LN(F45/F46) -> -0.0094212223 | M45: =LN(G45/G46) -> -0.021094766 | N45: =$D$5*I45+$D$6*J45+$D$7*K45+$D$8*L45+$D$9*M45 -> -0.010129464 | P45: =$C$10*N45 -> -5064.7318
...

Sheet Charts
A1: Bin | B1: Frequency | C1: Normal Curve | E1: Date | F1: Portfolio Value (Rs) | G1: Baseline | I1: Rolling VaR 95% (Rs) | J1: Rolling VaR 99% (Rs) | N1: Asset | O1: Standalone VaR 95% (Rs) | P1: Param VaR 95% if diversified
A2: -0.05 | B2: {=FREQUENCY(Calculation!$N$16:$N$1252,Charts!$A$2:$A$42)} -> 0 | C2: =(_xlfn.NORM.DIST(A2,AVERAGE(Calculation!$N$16:$N$1252),_xlfn.STDEV.S(Calculation!$N$16:$N$1252),FALSE))*0.0025*COUNT(Calculation!$N$16:$N$1252) -> 6.5340427e-05 | E2: =Calculation!B16 -> 46185 | F2: =F3*(1+Calculation!N16) -> 531245.77 | G2: =Calculation!$C$10 -> 500000 | I2: =ABS(PERCENTILE(OFFSET(Calculation!$N$16, ROW()-2, 0, 30, 1), 0.05))*500000 -> 5817.3162 | J2: =ABS(PERCENTILE(OFFSET(Calculation!$N$16, ROW()-2, 0, 30, 1), 0.01))*500000 -> 7368.0784 | N2: {=Summary!A5:A9} -> Nestle India | O2: {=Summary!F47:F51} -> 2177.6234 | R2: Σ | S2: Nestle_India | T2: Pidilite_Industries | U2: Divis_Laboratories | V2: Bosch | W2: UltraTech_Cement
A3: =A2+0.25% -> -0.0475 | B3: 0 | C3: =(_xlfn.NORM.DIST(A3,AVERAGE(Calculation!$N$16:$N$1252),_xlfn.STDEV.S(Calculation!$N$16:$N$1252),FALSE))*0.0025*COUNT(Calculation!$N$16:$N$1252) -> 0.00022694241 | E3: =Calculation!B17 -> 46184 | F3: =F4*(1+Calculation!N17) -> 525538.36 | G3: =Calculation!$C$10 -> 500000 | I3: =ABS(PERCENTILE(OFFSET(Calculation!$N$16, ROW()-2, 0, 30, 1), 0.05))*500000 -> 5817.3162 | J3: =ABS(PERCENTILE(OFFSET(Calculation!$N$16, ROW()-2, 0, 30, 1), 0.01))*500000 -> 7368.0784 | N3: Pidilite Industries | O3: 2135.4765 | R3: Nestle_India | S3: 0.00014194026 | T3: 5.3041311e-05 | U3: 3.2666305e-05 | V3: 4.4765889e-05 | W3: 5.0551904e-05
A4: =A3+0.25% -> -0.045 | B4: 0 | C4: =(_xlfn.NORM.DIST(A4,AVERAGE(Calculation!$N$16:$N$1252),_xlfn.STDEV.S(Calculation!$N$16:$N$1252),FALSE))*0.0025*COUNT(Calculation!$N$16:$N$1252) -> 0.00073975267 | E4: =Calculation!B18 -> 46183 | F4: =F5*(1+Calculation!N18) -> 528036.17 | G4: =Calculation!$C$10 -> 500000 | I4: =ABS(PERCENTILE(OFFSET(Calculation!$N$16, ROW()-2, 0, 30, 1), 0.05))*500000 -> 5817.3162 | J4: =ABS(PERCENTILE(OFFSET(Calculation!$N$16, ROW()-2, 0, 30, 1), 0.01))*500000 -> 7368.0784 | N4: Divi's Laboratories | O4: 2301.745 | R4: Pidilite_Industries | S4: 5.3041311e-05 | T4: 0.00017927902 | U4: 5.273156e-05 | V4: 6.4315507e-05 | W4: 6.9559756e-05
A5: =A4+0.25% -> -0.0425 | B5: 0 | C5: =(_xlfn.NORM.DIST(A5,AVERAGE(Calculation!$N$16:$N$1252),_xlfn.STDEV.S(Calculation!$N$16:$N$1252),FALSE))*0.0025*COUNT(Calculation!$N$16:$N$1252) -> 0.0022630524 | E5: =Calculation!B19 -> 46182 | F5: =F6*(1+Calculation!N19) -> 526567.63 | G5: =Calculation!$C$10 -> 500000 | I5: =ABS(PERCENTILE(OFFSET(Calculation!$N$16, ROW()-2, 0, 30, 1), 0.05))*500000 -> 5817.3162 | J5: =ABS(PERCENTILE(OFFSET(Calculation!$N$16, ROW()-2, 0, 30, 1), 0.01))*500000 -> 7368.0784 | N5: Bosch Ltd | O5: 3025.7816 | R5: Divis_Laboratories | S5: 3.2666305e-05 | T5: 5.273156e-05 | U5: 0.00028552612 | V5: 5.9658334e-05 | W5: 6.2477359e-05
A6: =A5+0.25% -> -0.04 | B6: 0 | C6: =(_xlfn.NORM.DIST(A6,AVERAGE(Calculation!$N$16:$N$1252),_xlfn.STDEV.S(Calculation!$N$16:$N$1252),FALSE))*0.0025*COUNT(Calculation!$N$16:$N$1252) -> 0.0064974041 | E6: =Calculation!B20 -> 46181 | F6: =F7*(1+Calculation!N20) -> 516010.54 | G6: =Calculation!$C$10 -> 500000 | I6: =ABS(PERCENTILE(OFFSET(Calculation!$N$16, ROW()-2, 0, 30, 1), 0.05))*500000 -> 5817.3162 | J6: =ABS(PERCENTILE(OFFSET(Calculation!$N$16, ROW()-2, 0, 30, 1), 0.01))*500000 -> 7368.0784 | N6: UltraTech Cement | O6: 2368.663 | R6: Bosch | S6: 4.4765889e-05 | T6: 6.4315507e-05 | U6: 5.9658334e-05 | V6: 0.0002600416 | W6: 8.3871918e-05
A7: =A6+0.25% -> -0.0375 | B7: 0 | C7: =(_xlfn.NORM.DIST(A7,AVERAGE(Calculation!$N$16:$N$1252),_xlfn.STDEV.S(Calculation!$N$16:$N$1252),FALSE))*0.0025*COUNT(Calculation!$N$16:$N$1252) -> 0.017507427 | E7: =Calculation!B21 -> 46178 | F7: =F8*(1+Calculation!N21) -> 521006.08 | G7: =Calculation!$C$10 -> 500000 | I7: =ABS(PERCENTILE(OFFSET(Calculation!$N$16, ROW()-2, 0, 30, 1), 0.05))*500000 -> 5817.3162 | J7: =ABS(PERCENTILE(OFFSET(Calculation!$N$16, ROW()-2, 0, 30, 1), 0.01))*500000 -> 7368.0784 | N7: Portfolio (diversified) | O7: =Summary!F52 -> 12009.29 | P7: =Summary!B39 -> 8013.6618 | R7: UltraTech_Cement | S7: 5.0551904e-05 | T7: 6.9559756e-05 | U7: 6.2477359e-05 | V7: 8.3871918e-05 | W7: 0.00021082584
A8: =A7+0.25% -> -0.035 | B8: 0 | C8: =(_xlfn.NORM.DIST(A8,AVERAGE(Calculation!$N$16:$N$1252),_xlfn.STDEV.S(Calculation!$N$16:$N$1252),FALSE))*0.0025*COUNT(Calculation!$N$16:$N$1252) -> 0.044273308 | E8: =Calculation!B22 -> 46177 | F8: =F9*(1+Calculation!N22) -> 519867.43 | G8: =Calculation!$C$10 -> 500000 | I8: =ABS(PERCENTILE(OFFSET(Calculation!$N$16, ROW()-2, 0, 30, 1), 0.05))*500000 -> 5817.3162 | J8: =ABS(PERCENTILE(OFFSET(Calculation!$N$16, ROW()-2, 0, 30, 1), 0.01))*500000 -> 7368.0784
A9: =A8+0.25% -> -0.0325 | B9: 2 | C9: =(_xlfn.NORM.DIST(A9,AVERAGE(Calculation!$N$16:$N$1252),_xlfn.STDEV.S(Calculation!$N$16:$N$1252),FALSE))*0.0025*COUNT(Calculation!$N$16:$N$1252) -> 0.10507486 | E9: =Calculation!B23 -> 46176 | F9: =F10*(1+Calculation!N23) -> 523266.73 | G9: =Calculation!$C$10 -> 500000 | I9: =ABS(PERCENTILE(OFFSET(Calculation!$N$16, ROW()-2, 0, 30, 1), 0.05))*500000 -> 5817.3162 | J9: =ABS(PERCENTILE(OFFSET(Calculation!$N$16, ROW()-2, 0, 30, 1), 0.01))*500000 -> 7368.0784
A10: =A9+0.25% -> -0.03 | B10: 3 | C10: =(_xlfn.NORM.DIST(A10,AVERAGE(Calculation!$N$16:$N$1252),_xlfn.STDEV.S(Calculation!$N$16:$N$1252),FALSE))*0.0025*COUNT(Calculation!$N$16:$N$1252) -> 0.23404148 | E10: =Calculation!B24 -> 46175 | F10: =F11*(1+Calculation!N24) -> 521209.98 | G10: =Calculation!$C$10 -> 500000 | I10: =ABS(PERCENTILE(OFFSET(Calculation!$N$16, ROW()-2, 0, 30, 1), 0.05))*500000 -> 5817.3162 | J10: =ABS(PERCENTILE(OFFSET(Calculation!$N$16, ROW()-2, 0, 30, 1), 0.01))*500000 -> 7368.0784
A11: =A10+0.25% -> -0.0275 | B11: 0 | C11: =(_xlfn.NORM.DIST(A11,AVERAGE(Calculation!$N$16:$N$1252),_xlfn.STDEV.S(Calculation!$N$16:$N$1252),FALSE))*0.0025*COUNT(Calculation!$N$16:$N$1252) -> 0.48924237 | E11: =Calculation!B25 -> 46174 | F11: =F12*(1+Calculation!N25) -> 520164.75 | G11: =Calculation!$C$10 -> 500000 | I11: =ABS(PERCENTILE(OFFSET(Calculation!$N$16, ROW()-2, 0, 30, 1), 0.05))*500000 -> 5817.3162 | J11: =ABS(PERCENTILE(OFFSET(Calculation!$N$16, ROW()-2, 0, 30, 1), 0.01))*500000 -> 7368.0784
A12: =A11+0.25% -> -0.025 | B12: 0 | C12: =(_xlfn.NORM.DIST(A12,AVERAGE(Calculation!$N$16:$N$1252),_xlfn.STDEV.S(Calculation!$N$16:$N$1252),FALSE))*0.0025*COUNT(Calculation!$N$16:$N$1252) -> 0.95982591 | E12: =Calculation!B26 -> 46171 | F12: =F13*(1+Calculation!N26) -> 528573.95 | G12: =Calculation!$C$10 -> 500000 | I12: =ABS(PERCENTILE(OFFSET(Calculation!$N$16, ROW()-2, 0, 30, 1), 0.05))*500000 -> 5492.7965 | J12: =ABS(PERCENTILE(OFFSET(Calculation!$N$16, ROW()-2, 0, 30, 1), 0.01))*500000 -> 5858.1235
A13: =A12+0.25% -> -0.0225 | B13: 0 | C13: =(_xlfn.NORM.DIST(A13,AVERAGE(Calculation!$N$16:$N$1252),_xlfn.STDEV.S(Calculation!$N$16:$N$1252),FALSE))*0.0025*COUNT(Calculation!$N$16:$N$1252) -> 1.7672503 | E13: =Calculation!B27 -> 46169 | F13: =F14*(1+Calculation!N27) -> 530832.98 | G13: =Calculation!$C$10 -> 500000 | I13: =ABS(PERCENTILE(OFFSET(Calculation!$N$16, ROW()-2, 0, 30, 1), 0.05))*500000 -> 5492.7965 | J13: =ABS(PERCENTILE(OFFSET(Calculation!$N$16, ROW()-2, 0, 30, 1), 0.01))*500000 -> 5858.1235
A14: =A13+0.25% -> -0.02 | B14: 3 | C14: =(_xlfn.NORM.DIST(A14,AVERAGE(Calculation!$N$16:$N$1252),_xlfn.STDEV.S(Calculation!$N$16:$N$1252),FALSE))*0.0025*COUNT(Calculation!$N$16:$N$1252) -> 3.0538019 | E14: =Calculation!B28 -> 46168 | F14: =F15*(1+Calculation!N28) -> 528977.99 | G14: =Calculation!$C$10 -> 500000 | I14: =ABS(PERCENTILE(OFFSET(Calculation!$N$16, ROW()-2, 0, 30, 1), 0.05))*500000 -> 5817.3162 | J14: =ABS(PERCENTILE(OFFSET(Calculation!$N$16, ROW()-2, 0, 30, 1), 0.01))*500000 -> 7032.9143
A15: =A14+0.25% -> -0.0175 | B15: 1 | C15: =(_xlfn.NORM.DIST(A15,AVERAGE(Calculation!$N$16:$N$1252),_xlfn.STDEV.S(Calculation!$N$16:$N$1252),FALSE))*0.0025*COUNT(Calculation!$N$16:$N$1252) -> 4.9524585 | E15: =Calculation!B29 -> 46167 | F15: =F16*(1+Calculation!N29) -> 530133.91 | G15: =Calculation!$C$10 -> 500000 | I15: =ABS(PERCENTILE(OFFSET(Calculation!$N$16, ROW()-2, 0, 30, 1), 0.05))*500000 -> 5817.3162 | J15: =ABS(PERCENTILE(OFFSET(Calculation!$N$16, ROW()-2, 0, 30, 1), 0.01))*500000 -> 7032.9143
A16: =A15+0.25% -> -0.015 | B16: 5 | C16: =(_xlfn.NORM.DIST(A16,AVERAGE(Calculation!$N$16:$N$1252),_xlfn.STDEV.S(Calculation!$N$16:$N$1252),FALSE))*0.0025*COUNT(Calculation!$N$16:$N$1252) -> 7.5376857 | E16: =Calculation!B30 -> 46164 | F16: =F17*(1+Calculation!N30) -> 530747.32 | G16: =Calculation!$C$10 -> 500000 | I16: =ABS(PERCENTILE(OFFSET(Calculation!$N$16, ROW()-2, 0, 30, 1), 0.05))*500000 -> 5817.3162 | J16: =ABS(PERCENTILE(OFFSET(Calculation!$N$16, ROW()-2, 0, 30, 1), 0.01))*500000 -> 7032.9143
A17: =A16+0.25% -> -0.0125 | B17: 6 | C17: =(_xlfn.NORM.DIST(A17,AVERAGE(Calculation!$N$16:$N$1252),_xlfn.STDEV.S(Calculation!$N$16:$N$1252),FALSE))*0.0025*COUNT(Calculation!$N$16:$N$1252) -> 10.766942 | E17: =Calculation!B31 -> 46163 | F17: =F18*(1+Calculation!N31) -> 525225.71 | G17: =Calculation!$C$10 -> 500000 | I17: =ABS(PERCENTILE(OFFSET(Calculation!$N$16, ROW()-2, 0, 30, 1), 0.05))*500000 -> 5817.3162 | J17: =ABS(PERCENTILE(OFFSET(Calculation!$N$16, ROW()-2, 0, 30, 1), 0.01))*500000 -> 7032.9143
A18: =A17+0.25% -> -0.01 | B18: 9 | C18: =(_xlfn.NORM.DIST(A18,AVERAGE(Calculation!$N$16:$N$1252),_xlfn.STDEV.S(Calculation!$N$16:$N$1252),FALSE))*0.0025*COUNT(Calculation!$N$16:$N$1252) -> 14.433909 | E18: =Calculation!B32 -> 46162 | F18: =F19*(1+Calculation!N32) -> 529764.92 | G18: =Calculation!$C$10 -> 500000 | I18: =ABS(PERCENTILE(OFFSET(Calculation!$N$16, ROW()-2, 0, 30, 1), 0.05))*500000 -> 5817.3162 | J18: =ABS(PERCENTILE(OFFSET(Calculation!$N$16, ROW()-2, 0, 30, 1), 0.01))*500000 -> 7032.9143
A19: =A18+0.25% -> -0.0075 | B19: 15 | C19: =(_xlfn.NORM.DIST(A19,AVERAGE(Calculation!$N$16:$N$1252),_xlfn.STDEV.S(Calculation!$N$16:$N$1252),FALSE))*0.0025*COUNT(Calculation!$N$16:$N$1252) -> 18.159868 | E19: =Calculation!B33 -> 46161 | F19: =F20*(1+Calculation!N33) -> 531332.37 | G19: =Calculation!$C$10 -> 500000 | I19: =ABS(PERCENTILE(OFFSET(Calculation!$N$16, ROW()-2, 0, 30, 1), 0.05))*500000 -> 5817.3162 | J19: =ABS(PERCENTILE(OFFSET(Calculation!$N$16, ROW()-2, 0, 30, 1), 0.01))*500000 -> 7032.9143
... A42: =A41+0.25% -> 0.05 | B42: 0 | C42: =(_xlfn.NORM.DIST(A42,AVERAGE(Calculation!$N$16:$N$1252),_xlfn.STDEV.S(Calculation!$N$16:$N$1252),FALSE))*0.0025*COUNT(Calculation!$N$16:$N$1252) -> 8.8214243e-05 | E42: =Calculation!B56 -> 46127 | F42: =F43*(1+Calculation!N56) -> 501017.73 | G42: =Calculation!$C$10 -> 500000 | I42: =ABS(PERCENTILE(OFFSET(Calculation!$N$16, ROW()-2, 0, 30, 1), 0.05))*500000 -> 15842.06 | J42: =ABS(PERCENTILE(OFFSET(Calculation!$N$16, ROW()-2, 0, 30, 1), 0.01))*500000 -> 16280.832
E43: =Calculation!B57 -> 46125 | F43: =F44*(1+Calculation!N57) -> 493082.29 | G43: =Calculation!$C$10 -> 500000 | I43: =ABS(PERCENTILE(OFFSET(Calculation!$N$16, ROW()-2, 0, 30, 1), 0.05))*500000 -> 15842.06 | J43: =ABS(PERCENTILE(OFFSET(Calculation!$N$16, ROW()-2, 0, 30, 1), 0.01))*500000 -> 16280.832
E44: =Calculation!B58 -> 46122 | F44: =F45*(1+Calculation!N58) -> 500573.42 | G44: =Calculation!$C$10 -> 500000 | I44: =ABS(PERCENTILE(OFFSET(Calculation!$N$16, ROW()-2, 0, 30, 1), 0.05))*500000 -> 15842.06 | J44: =ABS(PERCENTILE(OFFSET(Calculation!$N$16, ROW()-2, 0, 30, 1), 0.01))*500000 -> 16280.832
E45: =Calculation!B59 -> 46121 | F45: =F46*(1+Calculation!N59) -> 492945.67 | G45: =Calculation!$C$10 -> 500000 | I45: =ABS(PERCENTILE(OFFSET(Calculation!$N$16, ROW()-2, 0, 30, 1), 0.05))*500000 -> 15842.06 | J45: =ABS(PERCENTILE(OFFSET(Calculation!$N$16, ROW()-2, 0, 30, 1), 0.01))*500000 -> 16280.832
E46: =Calculation!B60 -> 46120 | F46: =F47*(1+Calculation!N60) -> 490168.75 | G46: =Calculation!$C$10 -> 500000 | I46: =ABS(PERCENTILE(OFFSET(Calculation!$N$16, ROW()-2, 0, 30, 1), 0.05))*500000 -> 15842.06 | J46: =ABS(PERCENTILE(OFFSET(Calculation!$N$16, ROW()-2, 0, 30, 1), 0.01))*500000 -> 16280.832
E47: =Calculation!B61 -> 46119 | F47: =F48*(1+Calculation!N61) -> 473669.05 | G47: =Calculation!$C$10 -> 500000 | I47: =ABS(PERCENTILE(OFFSET(Calculation!$N$16, ROW()-2, 0, 30, 1), 0.05))*500000 -> 15842.06 | J47: =ABS(PERCENTILE(OFFSET(Calculation!$N$16, ROW()-2, 0, 30, 1), 0.01))*500000 -> 16280.832
E48: =Calculation!B62 -> 46118 | F48: =F49*(1+Calculation!N62) -> 472589.61 | G48: =Calculation!$C$10 -> 500000 | I48: =ABS(PERCENTILE(OFFSET(Calculation!$N$16, ROW()-2, 0, 30, 1), 0.05))*500000 -> 15842.06 | J48: =ABS(PERCENTILE(OFFSET(Calculation!$N$16, ROW()-2, 0, 30, 1), 0.01))*500000 -> 16280.832
E49: =Calculation!B63 -> 46114 | F49: =F50*(1+Calculation!N63) -> 463406.58 | G49: =Calculation!$C$10 -> 500000 | I49: =ABS(PERCENTILE(OFFSET(Calculation!$N$16, ROW()-2, 0, 30, 1), 0.05))*500000 -> 15842.06 | J49: =ABS(PERCENTILE(OFFSET(Calculation!$N$16, ROW()-2, 0, 30, 1), 0.01))*500000 -> 16280.832
E50: =Calculation!B64 -> 46113 | F50: =F51*(1+Calculation!N64) -> 462054.16 | G50: =Calculation!$C$10 -> 500000 | I50: =ABS(PERCENTILE(OFFSET(Calculation!$N$16, ROW()-2, 0, 30, 1), 0.05))*500000 -> 15842.06 | J50: =ABS(PERCENTILE(OFFSET(Calculation!$N$16, ROW()-2, 0, 30, 1), 0.01))*500000 -> 16280.832
E51: =Calculation!B65 -> 46111 | F51: =F52*(1+Calculation!N65) -> 455172.11 | G51: =Calculation!$C$10 -> 500000 | I51: =ABS(PERCENTILE(OFFSET(Calculation!$N$16, ROW()-2, 0, 30, 1), 0.05))*500000 -> 15842.06 | J51: =ABS(PERCENTILE(OFFSET(Calculation!$N$16, ROW()-2, 0, 30, 1), 0.01))*500000 -> 16280.832
E52: =Calculation!B66 -> 46108 | F52: =F53*(1+Calculation!N66) -> 465078.6 | G52: =Calculation!$C$10 -> 500000 | I52: =ABS(PERCENTILE(OFFSET(Calculation!$N$16, ROW()-2, 0, 30, 1), 0.05))*500000 -> 15842.06 | J52: =ABS(PERCENTILE(OFFSET(Calculation!$N$16, ROW()-2, 0, 30, 1), 0.01))*500000 -> 16280.832
E53: =Calculation!B67 -> 46106 | F53: =F54*(1+Calculation!N67) -> 473238.43 | G53: =Calculation!$C$10 -> 500000 | I53: =ABS(PERCENTILE(OFFSET(Calculation!$N$16, ROW()-2, 0, 30, 1), 0.05))*500000 -> 15842.06 | J53: =ABS(PERCENTILE(OFFSET(Calculation!$N$16, ROW()-2, 0, 30, 1), 0.01))*500000 -> 16280.832
E54: =Calculation!B68 -> 46105 | F54: =F55*(1+Calculation!N68) -> 464923.65 | G54: =Calculation!$C$10 -> 500000 | I54: =ABS(PERCENTILE(OFFSET(Calculation!$N$16, ROW()-2, 0, 30, 1), 0.05))*500000 -> 15842.06 | J54: =ABS(PERCENTILE(OFFSET(Calculation!$N$16, ROW()-2, 0, 30, 1), 0.01))*500000 -> 16280.832
... E218: =Calculation!B232 -> 45863 | F218: =F219*(1+Calculation!N232) -> 517352.36 | G218: =Calculation!$C$10 -> 500000 | I218: =ABS(PERCENTILE(OFFSET(Calculation!$N$16, ROW()-2, 0, 30, 1), 0.05))*500000 -> 5150.7101 | J218: =ABS(PERCENTILE(OFFSET(Calculation!$N$16, ROW()-2, 0, 30, 1), 0.01))*500000 -> 6913.5007
E219: =Calculation!B233 -> 45862 | F219: =F220*(1+Calculation!N233) -> 520696.09 | G219: =Calculation!$C$10 -> 500000
E220: =Calculation!B234 -> 45861 | F220: =F221*(1+Calculation!N234) -> 528344.3 | G220: =Calculation!$C$10 -> 500000
E221: =Calculation!B235 -> 45860 | F221: =F222*(1+Calculation!N235) -> 527950.89 | G221: =Calculation!$C$10 -> 500000
E222: =Calculation!B236 -> 45859 | F222: =F223*(1+Calculation!N236) -> 534492.28 | G222: =Calculation!$C$10 -> 500000
E223: =Calculation!B237 -> 45856 | F223: =F224*(1+Calculation!N237) -> 533726.47 | G223: =Calculation!$C$10 -> 500000
E224: =Calculation!B238 -> 45855 | F224: =F225*(1+Calculation!N238) -> 535992.72 | G224: =Calculation!$C$10 -> 500000
E225: =Calculation!B239 -> 45854 | F225: =F226*(1+Calculation!N239) -> 536217.46 | G225: =Calculation!$C$10 -> 500000
...

Sheet Nestlé India Limited
A4: BSE:500790 (MI Key: 4913237; SPCIQ Key: 877826)
A7: Entities: Nestlé India Ltd., S&P Asia Pacific Emerging BMI Consumer Staples (Sector) Index
A8: Metrics: Share Price, Volume
A45: SERIES NAME | B45: CATEGORY | C45: HIGH | D45: LOW | E45: AVERAGE | F45: CHANGE
A46: 500790-Share Price (Daily) | B46: Market Data | C46: 1,486.40 | D46: 804.89 | E46: 1,090.44 | F46: 456.23 | 49.61%
A47: S&P Asia Pacific Emerging BMI Consumer Staples (Sector) Index-Index Value (Daily) | B47: Market Data | C47: 552.90 | D47: 326.93 | E47: 408.73 | F47: -178.82 | -34.93%
A48: 500790-Volume (Daily) | B48: Market Data | C48: 951,340.00 | D48: 3,712.00 | E48: 72,552.63 | F48: 8,758.00 | 8.81%
A51: Pricing Date | B51: 500790-Share Price (Daily)(%) | C51: 500790-Volume (Daily) | D51: S&P Asia Pacific Emerging BMI Consumer Staples (Sector) Index-Index Value (Daily)(%)
A52: 46185 | B52: 49.611115 | C52: 108218 | D52: -34.927964
A53: 46184 | B53: 54.602321 | C53: 44897 | D53: -35.763008
A54: 46183 | B54: 56.380234 | C54: 95952 | D54: -35.432934
A55: 46182 | B55: 53.368112 | C55: 36150 | D55: -35.755898
A56: 46181 | B56: 52.1774 | C56: 46593 | D56: -36.143989
A57: 46178 | B57: 50.894258 | C57: 24257 | D57: -35.308525
A58: 46177 | B58: 50.187442 | C58: 419031 | D58: -35.211475
A59: 46176 | B59: 51.432525 | C59: 399831 | D59: -34.813002
A60: 46175 | B60: 52.090407 | C60: 37248 | D60: -34.018249
A61: 46174 | B61: 51.269414 | C61: 26370 | D61: -33.967962
A62: 46171 | B62: 54.721936 | C62: 238845 | D62: -33.894828
A63: 46170 | B63: NA | C63: NA | D63: -34.407499
A64: 46169 | B64: 55.216707 | C64: 31087 | D64: -33.978924
A65: 46168 | B65: 55.379818 | C65: 96914 | D65: -33.841447
A66: 46167 | B66: 53.737831 | C66: 56926 | D66: -33.447651
A67: 46164 | B67: 54.765432 | C67: 62718 | D67: -33.499467
A68: 46163 | B68: 52.889652 | C68: 35981 | D68: -33.315336
A69: 46162 | B69: 54.43921 | C69: 38166 | D69: -33.070288
A70: 46161 | B70: 55.657107 | C70: 120221 | D70: -32.709572
A71: 46160 | B71: 55.760411 | C71: 83636 | D71: -32.504392
A72: 46157 | B72: 55.532055 | C72: 52349 | D72: -31.691663
A73: 46156 | B73: 58.7236 | C73: 45577 | D73: -31.143389
A74: 46155 | B74: 59.691393 | C74: 47706 | D74: -31.151638
A75: 46154 | B75: 59.69683 | C75: 24644 | D75: -31.071029
... A81: 46146 | B81: 58.429999 | C81: 35413 | D81: -30.319807
A82: 46143 | B82: NA | C82: NA | D82: -30.525382
A83: 46142 | B83: 58.522429 | C83: 193503 | D83: -30.533254
A84: 46141 | B84: 59.424978 | C84: 78958 | D84: -29.824989
A85: 46140 | B85: 56.575968 | C85: 59313 | D85: -30.38559
A86: 46139 | B86: 54.009683 | C86: 48341 | D86: -30.034829
A87: 46136 | B87: 54.526202 | C87: 101499 | D87: -29.883146
A88: 46135 | B88: 53.330053 | C88: 113556 | D88: -29.568553
...

Sheet Pidilite Industries Limited
A2: Pidilite Industries Limited | Stock Chart
A4: NSEI:PIDILITIND (MI Key: 4986006; SPCIQ Key: 878761)
A7: Entities: Pidilite Industries Ltd., S&P Asia Pacific Emerging BMI Materials (Industry Group) Index
A8: Metrics: Share Price, Volume
A45: SERIES NAME | B45: CATEGORY | C45: HIGH | D45: LOW | E45: AVERAGE | F45: CHANGE
A46: PIDILITIND-Share Price (Daily) | B46: Market Data | C46: 2.63 | D46: -16.40 | E46: -3.62 | F46: 0.79
A47: PIDILITIND-Volume (Daily) | B47: Market Data | C47: 5.49M | D47: 62,310.00 | E47: 705,716.69 | F47: 487,271.00 | 63.53%
A48: S&P Asia Pacific Emerging BMI Materials (Industry Group) Index-Index Value (Daily) | B48: Market Data | C48: 35.97 | D48: -3.17 | E48: 17.33 | F48: 21.53
A51: Pricing Date | B51: PIDILITIND-Share Price (Daily)(%) | C51: PIDILITIND-Volume (Daily) | D51: S&P Asia Pacific Emerging BMI Materials (Industry Group) Index-Index Value (Daily)(%)
A52: 46185 | B52: 0.79096787 | C52: 1254231 | D52: 21.528019
A53: 46184 | B53: -1.618038 | C53: 613282 | D53: 17.709014
A54: 46183 | B54: -1.1126063 | C54: 1866212 | D54: 17.649256
A55: 46182 | B55: -2.7339263 | C55: 536175 | D55: 18.985602
A56: 46181 | B56: -4.178017 | C56: 417045 | D56: 17.096289
A57: 46178 | B57: -3.0752568 | C57: 489330 | D57: 21.429884
A58: 46177 | B58: -3.4362795 | C58: 646986 | D58: 22.783451
A59: 46176 | B59: -3.5609964 | C59: 836338 | D59: 24.428947
A60: 46175 | B60: -4.5193475 | C60: 948386 | D60: 24.832889
A61: 46174 | B61: -4.3486823 | C61: 690657 | D61: 23.44996
A62: 46171 | B62: -2.6682858 | C62: 4438929 | D62: 22.876987
A63: 46170 | B63: NA | C63: NA | D63: 23.336976
A64: 46169 | B64: -2.8061308 | C64: 323780 | D64: 24.213523
A65: 46168 | B65: -2.9505399 | C65: 454638 | D65: 24.983098
A66: 46167 | B66: -3.0358725 | C66: 593426 | D66: 23.668886
A67: 46164 | B67: -2.9571039 | C67: 533048 | D67: 22.891293
A68: 46163 | B68: -3.3246907 | C68: 465411 | D68: 20.68905
A69: 46162 | B69: -4.453707 | C69: 356329 | D69: 21.127643
A70: 46161 | B70: -4.4405789 | C70: 617156 | D70: 21.406027
A71: 46160 | B71: -4.8081657 | C71: 655599 | D71: 22.748082
A72: 46157 | B72: -3.6594572 | C72: 909039 | D72: 24.658919
A73: 46156 | B73: -2.6026453 | C73: 1213793 | D73: 27.566113
A74: 46155 | B74: -5.1101119 | C74: 1124814 | D74: 28.844356
A75: 46154 | B75: -4.6243723 | C75: 1764144 | D75: 28.117427
... A81: 46146 | B81: -10.426991 | C81: 649397 | D81: 26.95086
A82: 46143 | B82: NA | C82: NA | D82: 26.599723
A83: 46142 | B83: -9.698382 | C83: 1333712 | D83: 26.576982
A84: 46141 | B84: -8.8253635 | C84: 364945 | D84: 28.466715
A85: 46140 | B85: -8.5890577 | C85: 390142 | D85: 26.679355
A86: 46139 | B86: -8.1492665 | C86: 356391 | D86: 27.626032
A87: 46136 | B87: -8.4774689 | C87: 506429 | D87: 27.09345
...

Sheet Divi's Laboratories Limited
A2: Divi's Laboratories Limited | Stock Chart
A4: NSEI:DIVISLAB (MI Key: 4810902; SPCIQ Key: 9249099)
A7: Entities: Divi's Laboratories Ltd., S&P Asia Pacific Emerging BMI Pharmaceuticals, Biotechnology & Life Sciences (Ind Group) Index
A8: Metrics: Share Price, Volume
A45: SERIES NAME | B45: CATEGORY | C45: HIGH | D45: LOW | E45: AVERAGE | F45: CHANGE
A46: DIVISLAB-Share Price (Daily) | B46: Market Data | C46: 3.84 | D46: -15.40 | E46: -5.15 | F46: -1.29
A47: DIVISLAB-Volume (Daily) | B47: Market Data | C47: 1.93M | D47: 32,977.00 | E47: 367,040.87 | F47: -268,620.00 | -62.26%
A48: S&P Asia Pacific Emerging BMI Pharmaceuticals, Biotechnology & Life Sciences (Ind Group) Index-Index Value (Daily) | B48: Market Data | C48: 14.30 | D48: -9.07 | E48: 2.80 | F48: -6.99
A51: Pricing Date | B51: DIVISLAB-Share Price (Daily)(%) | C51: DIVISLAB-Volume (Daily) | D51: S&P Asia Pacific Emerging BMI Pharmaceuticals, Biotechnology & Life Sciences (Ind Group) Index-Index Value (Daily)(%)
A52: 46185 | B52: -1.2936803 | C52: 162810 | D52: -6.990235
A53: 46184 | B53: -1.0334572 | C53: 228572 | D53: -8.9538083
A54: 46183 | B54: -1.2862454 | C54: 405743 | D54: -8.3245044
A55: 46182 | B55: 0.41635688 | C55: 912179 | D55: -8.7743274
A56: 46181 | B56: -3.0334572 | C56: 456406 | D56: -9.0720454
A57: 46178 | B57: -1.5167286 | C57: 200964 | D57: -7.0425742
A58: 46177 | B58: -1.9107807 | C58: 347823 | D58: -6.8978658
A59: 46176 | B59: -2.2081784 | C59: 563313 | D59: -6.7101034
A60: 46175 | B60: -2.8550186 | C60: 362800 | D60: -5.3031264
A61: 46174 | B61: -2.5501859 | C61: 125379 | D61: -4.0233794
A62: 46171 | B62: -0.86245353 | C62: 612037 | D62: -3.1388342
A63: 46170 | B63: NA | C63: NA | D63: -4.9038176
A64: 46169 | B64: 1.0780669 | C64: 155051 | D64: -3.0412067
A65: 46168 | B65: 0.41635688 | C65: 309440 | D65: -2.5677402
A66: 46167 | B66: 0.46840149 | C66: 874049 | D66: -1.9903144
A67: 46164 | B67: 2.4089219 | C67: 354149 | D67: -2.4933496
A68: 46163 | B68: 1.9776952 | C68: 151586 | D68: -2.2065484
A69: 46162 | B69: 2.4981413 | C69: 957736 | D69: -3.0308453
A70: 46161 | B70: 2.7806691 | C70: 322081 | D70: -3.1154585
A71: 46160 | B71: 1.6356877 | C71: 340352 | D71: -3.0589818
A72: 46157 | B72: 0.52788104 | C72: 321270 | D72: -1.5953461
A73: 46156 | B73: 2.9219331 | C73: 424282 | D73: -0.67516447
A74: 46155 | B74: 1.0557621 | C74: 513807 | D74: -0.27680365
A75: 46154 | B75: -1.204461 | C75: 156166 | D75: 0.20824216
... A81: 46146 | B81: -1.5687732 | C81: 371945 | D81: -0.041021355
A82: 46143 | B82: NA | C82: NA | D82: -0.57619761
A83: 46142 | B83: -3.3085502 | C83: 379741 | D83: -0.56933404
A84: 46141 | B84: -2.8401487 | C84: 324770 | D84: -0.52102698
A85: 46140 | B85: -4.3494424 | C85: 271770 | D85: -0.5146355
A86: 46139 | B86: -3.6877323 | C86: 289657 | D86: -0.38761439
A87: 46136 | B87: -5.4052045 | C87: 316970 | D87: -0.73243307
...

Sheet Bosch Limited
A2: Bosch Limited | Stock Chart
A4: BSE:500530 (MI Key: 4911941; SPCIQ Key: 9830297)
A7: Entities: Bosch Ltd., S&P Asia Pacific Emerging BMI Consumer Staples (Sector) Index
A8: Metrics: Share Price, Volume
A45: SERIES NAME | B45: CATEGORY | C45: HIGH | D45: LOW | E45: AVERAGE | F45: CHANGE
A46: 500530-Share Price (Daily) | B46: Market Data | C46: 31.69 | D46: -8.82 | E46: 16.38 | F46: 23.93
A47: 500530-Volume (Daily) | B47: Market Data | C47: 16,226.00 | D47: 69.00 | E47: 1,438.99 | F47: 3,764.00 | 1,767.14%
A48: S&P Asia Pacific Emerging BMI Consumer Staples (Sector) Index-Index Value (Daily) | B48: Market Data | C48: 5.72 | D48: -13.90 | E48: -1.98 | F48: -12.26
A51: Pricing Date | B51: 500530-Share Price (Daily)(%) | C51: 500530-Volume (Daily) | D51: S&P Asia Pacific Emerging BMI Consumer Staples (Sector) Index-Index Value (Daily)(%)
A52: 46185 | B52: 23.928354 | C52: 3977 | D52: -12.262982
A53: 46184 | B53: 19.140081 | C53: 2029 | D53: -13.388877
A54: 46183 | B54: 19.896901 | C54: 1349 | D54: -12.943836
A55: 46182 | B55: 19.993209 | C55: 3022 | D55: -13.379291
A56: 46181 | B56: 15.994123 | C56: 1360 | D56: -13.902556
A57: 46178 | B57: 18.179539 | C57: 8029 | D57: -12.776094
A58: 46177 | B58: 17.440331 | C58: 1901 | D58: -12.645242
A59: 46176 | B59: 19.709997 | C59: 2524 | D59: -12.107978
A60: 46175 | B60: 18.141302 | C60: 2494 | D60: -11.036408
A61: 46174 | B61: 16.320016 | C61: 2346 | D61: -10.968605
A62: 46171 | B62: 16.364124 | C62: 9878 | D62: -10.869998
A63: 46170 | B63: NA | C63: NA | D63: -11.561236
A64: 46169 | B64: 14.316903 | C64: 1532 | D64: -10.983385
A65: 46168 | B65: 13.761902 | C65: 2630 | D65: -10.798025
A66: 46167 | B66: 15.25793 | C66: 2123 | D66: -10.267067
A67: 46164 | B67: 14.414322 | C67: 16226 | D67: -10.336931
A68: 46163 | B68: 11.688819 | C68: 11792 | D68: -10.088666
A69: 46162 | B69: 16.840746 | C69: 2427 | D69: -9.7582662
A70: 46161 | B70: 17.732746 | C70: 1303 | D70: -9.27191
A71: 46160 | B71: 17.911241 | C71: 750 | D71: -8.9952657
A72: 46157 | B72: 19.62543 | C72: 1646 | D72: -7.8994581
A73: 46156 | B73: 17.283573 | C73: 5764 | D73: -7.1602172
A74: 46155 | B74: 15.248251 | C74: 796 | D74: -7.1713385
A75: 46154 | B75: 15.788338 | C75: 521 | D75: -7.0626526
... A81: 46146 | B81: 13.678604 | C81: 1136 | D81: -6.0497757
A82: 46143 | B82: NA | C82: NA | D82: -6.3269535
A83: 46142 | B83: 14.264862 | C83: 1528 | D83: -6.337568
A84: 46141 | B84: 15.346463 | C84: 1241 | D84: -5.3826105
A85: 46140 | B85: 18.536371 | C85: 862 | D85: -6.1384719
A86: 46139 | B86: 18.040234 | C86: 1009 | D86: -5.6655388
A87: 46136 | B87: 16.39776 | C87: 1922 | D87: -5.4610233
...

Sheet UltraTech Cement Limited
A2: UltraTech Cement Limited | Stock Chart
A4: NSEI:ULTRACEMCO (MI Key: 4982273; SPCIQ Key: 13192517)
A7: Entities: UltraTech Cement Ltd., S&P Asia Pacific Emerging BMI Materials (Industry Group) Index
A8: Metrics: Share Price, Volume
A45: SERIES NAME | B45: CATEGORY | C45: HIGH | D45: LOW | E45: AVERAGE | F45: CHANGE
A46: ULTRACEMCO-Share Price (Daily) | B46: Market Data | C46: 15.27 | D46: -8.49 | E46: 5.98 | F46: -1.82
A47: ULTRACEMCO-Volume (Daily) | B47: Market Data | C47: 1.78M | D47: 14,465.00 | E47: 282,903.62 | F47: 11,169.00 | 6.16%
A48: S&P Asia Pacific Emerging BMI Materials (Industry Group) Index-Index Value (Daily) | B48: Market Data | C48: 35.97 | D48: -3.17 | E48: 17.33 | F48: 21.53
A51: Pricing Date | B51: ULTRACEMCO-Share Price (Daily)(%) | C51: ULTRACEMCO-Volume (Daily) | D51: S&P Asia Pacific Emerging BMI Materials (Industry Group) Index-Index Value (Daily)(%)
A52: 46185 | B52: -1.8193058 | C52: 192524 | D52: 21.528019
A53: 46184 | B53: -4.3539698 | C53: 236130 | D53: 17.709014
A54: 46183 | B54: -4.0360329 | C54: 470400 | D54: 17.649256
A55: 46182 | B55: -3.6386117 | C55: 257371 | D55: 18.985602
A56: 46181 | B56: -4.6630752 | C56: 285585 | D56: 17.096289
A57: 46178 | B57: -3.6297801 | C57: 424664 | D57: 21.429884
A58: 46177 | B58: -2.8790956 | C58: 541327 | D58: 22.783451
A59: 46176 | B59: -1.9606111 | C59: 412934 | D59: 24.428947
A60: 46175 | B60: -1.3953899 | C60: 413041 | D60: 24.832889
A61: 46174 | B61: -0.80367394 | C61: 497866 | D61: 23.44996
A62: 46171 | B62: 1.4042215 | C62: 1776975 | D62: 22.876987
A63: 46170 | B63: NA | C63: NA | D63: 23.336976
A64: 46169 | B64: 3.2323589 | C64: 243628 | D64: 24.213523
A65: 46168 | B65: 2.6494745 | C65: 210716 | D65: 24.983098
A66: 46167 | B66: 3.5591274 | C66: 229618 | D66: 23.668886
A67: 46164 | B67: 2.1725691 | C67: 340427 | D67: 22.891293
A68: 46163 | B68: 1.3335688 | C68: 244967 | D68: 20.68905
A69: 46162 | B69: 0.75951603 | C69: 168245 | D69: 21.127643
A70: 46161 | B70: 0.39742118 | C70: 347784 | D70: 21.406027
A71: 46160 | B71: 2.1019165 | C71: 233668 | D71: 22.748082
A72: 46157 | B72: 1.4483794 | C72: 284388 | D72: 24.658919
A73: 46156 | B73: 3.2588537 | C73: 220410 | D73: 27.566113
A74: 46155 | B74: 2.2078954 | C74: 453482 | D74: 28.844356
A75: 46154 | B75: 1.7044953 | C75: 343980 | D75: 28.117427
... A81: 46146 | B81: 3.8417381 | C81: 461238 | D81: 26.95086
A82: 46143 | B82: NA | C82: NA | D82: 26.599723
A83: 46142 | B83: 2.322706 | C83: 719688 | D83: 26.576982
A84: 46141 | B84: 4.5041067 | C84: 361932 | D84: 28.466715
A85: 46140 | B85: 4.3628014 | C85: 509322 | D85: 26.679355
A86: 46139 | B86: 6.0672967 | C86: 567601 | D86: 27.626032
A87: 46136 | B87: 5.9613177 | C87: 349586 | D87: 27.09345
...
